<sdf version='1.6'>
  <model name='ur10'>
    <link name='base_link'>
      <pose frame=''>0 0 0 0 -0 0</pose>
      <inertial>
        <pose frame=''>0 0 0.81 0 -0 0</pose>
        <mass>5</mass>
        <inertia>
          <ixx>1.16811</ixx>
          <ixy>0</ixy>
          <ixz>0</ixz>
          <iyy>1.16811</iyy>
          <iyz>0</iyz>
          <izz>1.01125</izz>
        </inertia>
      </inertial>
      <collision name='base_link_fixed_joint_lump__pedistal_link_collision'>
        <pose frame=''>0 0 0.45 0 -0 0</pose>
        <geometry>
          <box>
            <size>0.15 0.15 0.9</size>
          </box>
        </geometry>
      </collision>
      <collision name='base_link_fixed_joint_lump__ur10_base_link_collision_1'>
        <pose frame=''>0 0 0.9 0 -0 0</pose>
        <geometry>
          <mesh>
            <scale>1 1 1</scale>
            <uri>model://ur_description/meshes/ur10/collision/base.stl</uri>
          </mesh>
        </geometry>
        <surface>
          <contact>
            <ode/>
          </contact>
          <friction>
            <ode/>
          </friction>
        </surface>
      </collision>
      <visual name='base_link_fixed_joint_lump__pedistal_link_visual'>
        <pose frame=''>0 0 0.45 0 -0 0</pose>
        <geometry>
          <box>
            <size>0.15 0.15 0.9</size>
          </box>
        </geometry>
      </visual>
      <visual name='base_link_fixed_joint_lump__ur10_base_link_visual_1'>
        <pose frame=''>0 0 0.9 0 -0 0</pose>
        <geometry>
          <mesh>
            <scale>1 1 1</scale>
            <uri>model://ur_description/meshes/ur10/visual/base.dae</uri>
          </mesh>
        </geometry>
        <material>
          <script>
            <uri>__default__</uri>
            <name>__default__</name>
          </script>
        </material>
      </visual>
      <velocity_decay/>
      <gravity>1</gravity>
      <velocity_decay/>
      <self_collide>0</self_collide>
    </link>
    <joint name='world_joint' type='revolute'>
      <child>base_link</child>
      <parent>world</parent>
      <axis>
        <limit>
          <lower>0</lower>
          <upper>0</upper>
        </limit>
        <dynamics>
          <damping>0</damping>
          <friction>0</friction>
          <spring_reference>0</spring_reference>
          <spring_stiffness>0</spring_stiffness>
        </dynamics>
        <use_parent_model_frame>1</use_parent_model_frame>
        <xyz>0 0 1</xyz>
      </axis>
    </joint>
    <link name='shoulder_link'>
      <pose frame=''>0 0 1.0273 0 -0 0</pose>
      <inertial>
        <pose frame=''>0 0 0 0 -0 0</pose>
        <mass>7.778</mass>
        <inertia>
          <ixx>0.0314743</ixx>
          <ixy>0</ixy>
          <ixz>0</ixz>
          <iyy>0.0314743</iyy>
          <iyz>0</iyz>
          <izz>0.0218756</izz>
        </inertia>
      </inertial>
      <collision name='shoulder_link_collision'>
        <pose frame=''>0 0 0 0 -0 0</pose>
        <geometry>
          <mesh>
            <scale>1 1 1</scale>
            <uri>model://ur_description/meshes/ur10/collision/shoulder.stl</uri>
          </mesh>
        </geometry>
        <surface>
          <contact>
            <ode/>
          </contact>
          <friction>
            <ode/>
          </friction>
        </surface>
      </collision>
      <visual name='shoulder_link_visual'>
        <pose frame=''>0 0 0 0 -0 0</pose>
        <geometry>
          <mesh>
            <scale>1 1 1</scale>
            <uri>model://ur_description/meshes/ur10/visual/shoulder.dae</uri>
          </mesh>
        </geometry>
        <material>
          <script>
            <uri>__default__</uri>
            <name>__default__</name>
          </script>
        </material>
      </visual>
      <gravity>1</gravity>
      <velocity_decay/>
      <self_collide>0</self_collide>
    </link>
    <joint name='shoulder_pan_joint' type='revolute'>
      <child>shoulder_link</child>
      <parent>base_link</parent>
      <axis>
        <xyz>0 0 1</xyz>
        <limit>
          <lower>-6.28319</lower>
          <upper>6.28319</upper>
          <effort>330</effort>
          <velocity>2.16</velocity>
        </limit>
        <dynamics>
          <damping>0</damping>
          <friction>0</friction>
          <spring_reference>0</spring_reference>
          <spring_stiffness>0</spring_stiffness>
        </dynamics>
        <use_parent_model_frame>1</use_parent_model_frame>
      </axis>
    </joint>
    <link name='upper_arm_link'>
      <pose frame=''>0 0.220941 1.0273 0 0.785398 0</pose>
      <inertial>
        <pose frame=''>0 0 0.306 0 -0 0</pose>
        <mass>12.93</mass>
        <inertia>
          <ixx>0.421754</ixx>
          <ixy>0</ixy>
          <ixz>0</ixz>
          <iyy>0.421754</iyy>
          <iyz>0</iyz>
          <izz>0.0363656</izz>
        </inertia>
      </inertial>
      <collision name='upper_arm_link_collision'>
        <pose frame=''>0 0 0 0 -0 0</pose>
        <geometry>
          <mesh>
            <scale>1 1 1</scale>
            <uri>model://ur_description/meshes/ur10/collision/upperarm.stl</uri>
          </mesh>
        </geometry>
        <surface>
          <contact>
            <ode/>
          </contact>
          <friction>
            <ode/>
          </friction>
        </surface>
      </collision>
      <visual name='upper_arm_link_visual'>
        <pose frame=''>0 0 0 0 -0 0</pose>
        <geometry>
          <mesh>
            <scale>1 1 1</scale>
            <uri>model://ur_description/meshes/ur10/visual/upperarm.dae</uri>
          </mesh>
        </geometry>
        <material>
          <script>
            <uri>__default__</uri>
            <name>__default__</name>
          </script>
        </material>
      </visual>
      <gravity>1</gravity>
      <velocity_decay/>
      <self_collide>0</self_collide>
    </link>
    <joint name='shoulder_lift_joint' type='revolute'>
      <child>upper_arm_link</child>
      <parent>shoulder_link</parent>
      <axis>
        <xyz>0 1 0</xyz>
        <limit>
          <lower>-6.28319</lower>
          <upper>6.28319</upper>
          <effort>330</effort>
          <velocity>2.16</velocity>
        </limit>
        <dynamics>
          <damping>0</damping>
          <friction>0</friction>
          <spring_reference>0</spring_reference>
          <spring_stiffness>0</spring_stiffness>
        </dynamics>
        <use_parent_model_frame>1</use_parent_model_frame>
      </axis>
    </joint>
    <link name='forearm_link'>
      <pose frame=''>0.432749 0.049041 1.46005 3.14159 1.57079 3.14159</pose>
      <inertial>
        <pose frame=''>0 0 0.28615 0 -0 0</pose>
        <mass>3.87</mass>
        <inertia>
          <ixx>0.11107</ixx>
          <ixy>0</ixy>
          <ixz>0</ixz>
          <iyy>0.11107</iyy>
          <iyz>0</iyz>
          <izz>0.0108844</izz>
        </inertia>
      </inertial>
      <collision name='forearm_link_collision'>
        <pose frame=''>0 0 0 0 -0 0</pose>
        <geometry>
          <mesh>
            <scale>1 1 1</scale>
            <uri>model://ur_description/meshes/ur10/collision/forearm.stl</uri>
          </mesh>
        </geometry>
        <surface>
          <contact>
            <ode/>
          </contact>
          <friction>
            <ode/>
          </friction>
        </surface>
      </collision>
      <visual name='forearm_link_visual'>
        <pose frame=''>0 0 0 0 -0 0</pose>
        <geometry>
          <mesh>
            <scale>1 1 1</scale>
            <uri>model://ur_description/meshes/ur10/visual/forearm.dae</uri>
          </mesh>
        </geometry>
        <material>
          <script>
            <uri>__default__</uri>
            <name>__default__</name>
          </script>
        </material>
      </visual>
      <gravity>1</gravity>
      <velocity_decay/>
      <self_collide>0</self_collide>
    </link>
    <joint name='elbow_joint' type='revolute'>
      <child>forearm_link</child>
      <parent>upper_arm_link</parent>
      <axis>
        <xyz>0 1 0</xyz>
        <limit>
          <lower>-6.28319</lower>
          <upper>6.28319</upper>
          <effort>150</effort>
          <velocity>3.15</velocity>
        </limit>
        <dynamics>
          <damping>0</damping>
          <friction>0</friction>
          <spring_reference>0</spring_reference>
          <spring_stiffness>0</spring_stiffness>
        </dynamics>
        <use_parent_model_frame>1</use_parent_model_frame>
      </axis>
    </joint>
    <link name='wrist_1_link'>
      <pose frame=''>1.00505 0.049041 1.46005 3.14159 0 3.14159</pose>
      <inertial>
        <pose frame=''>0 0 0 0 -0 0</pose>
        <mass>1.96</mass>
        <inertia>
          <ixx>0.00510825</ixx>
          <ixy>0</ixy>
          <ixz>0</ixz>
          <iyy>0.00510825</iyy>
          <iyz>0</iyz>
          <izz>0.0055125</izz>
        </inertia>
      </inertial>
      <collision name='wrist_1_link_collision'>
        <pose frame=''>0 0 0 0 -0 0</pose>
        <geometry>
          <mesh>
            <scale>1 1 1</scale>
            <uri>model://ur_description/meshes/ur10/collision/wrist1.stl</uri>
          </mesh>
        </geometry>
        <surface>
          <contact>
            <ode/>
          </contact>
          <friction>
            <ode/>
          </friction>
        </surface>
      </collision>
      <visual name='wrist_1_link_visual'>
        <pose frame=''>0 0 0 0 -0 0</pose>
        <geometry>
          <mesh>
            <scale>1 1 1</scale>
            <uri>model://ur_description/meshes/ur10/visual/wrist1.dae</uri>
          </mesh>
        </geometry>
        <material>
          <script>
            <uri>__default__</uri>
            <name>__default__</name>
          </script>
        </material>
      </visual>
      <gravity>1</gravity>
      <velocity_decay/>
      <self_collide>0</self_collide>
    </link>
    <joint name='wrist_1_joint' type='revolute'>
      <child>wrist_1_link</child>
      <parent>forearm_link</parent>
      <axis>
        <xyz>0 1 0</xyz>
        <limit>
          <lower>-6.28319</lower>
          <upper>6.28319</upper>
          <effort>54</effort>
          <velocity>3.2</velocity>
        </limit>
        <dynamics>
          <damping>0</damping>
          <friction>0</friction>
          <spring_reference>0</spring_reference>
          <spring_stiffness>0</spring_stiffness>
        </dynamics>
        <use_parent_model_frame>1</use_parent_model_frame>
      </axis>
    </joint>
    <link name='wrist_2_link'>
      <pose frame=''>1.00505 0.163941 1.46005 3.14159 0 3.14159</pose>
      <inertial>
        <pose frame=''>0 0 0 0 -0 0</pose>
        <mass>1.96</mass>
        <inertia>
          <ixx>0.00510825</ixx>
          <ixy>0</ixy>
          <ixz>0</ixz>
          <iyy>0.00510825</iyy>
          <iyz>0</iyz>
          <izz>0.0055125</izz>
        </inertia>
      </inertial>
      <collision name='wrist_2_link_collision'>
        <pose frame=''>0 0 0 0 -0 0</pose>
        <geometry>
          <mesh>
            <scale>1 1 1</scale>
            <uri>model://ur_description/meshes/ur10/collision/wrist2.stl</uri>
          </mesh>
        </geometry>
        <surface>
          <contact>
            <ode/>
          </contact>
          <friction>
            <ode/>
          </friction>
        </surface>
      </collision>
      <visual name='wrist_2_link_visual'>
        <pose frame=''>0 0 0 0 -0 0</pose>
        <geometry>
          <mesh>
            <scale>1 1 1</scale>
            <uri>model://ur_description/meshes/ur10/visual/wrist2.dae</uri>
          </mesh>
        </geometry>
        <material>
          <script>
            <uri>__default__</uri>
            <name>__default__</name>
          </script>
        </material>
      </visual>
      <gravity>1</gravity>
      <velocity_decay/>
      <self_collide>0</self_collide>
    </link>
    <joint name='wrist_2_joint' type='revolute'>
      <child>wrist_2_link</child>
      <parent>wrist_1_link</parent>
      <axis>
        <xyz>0 0 -1</xyz>
        <limit>
          <lower>-6.28319</lower>
          <upper>6.28319</upper>
          <effort>54</effort>
          <velocity>3.2</velocity>
        </limit>
        <dynamics>
          <damping>0</damping>
          <friction>0</friction>
          <spring_reference>0</spring_reference>
          <spring_stiffness>0</spring_stiffness>
        </dynamics>
        <use_parent_model_frame>1</use_parent_model_frame>
      </axis>
    </joint>
    <link name='wrist_3_link'>
      <pose frame=''>1.00505 0.163941 1.34435 3.14159 0 3.14159</pose>
      <inertial>
        <pose frame=''>0 0.081196 0 0 -0 0</pose>
        <mass>0.602</mass>
        <inertia>
          <ixx>0.0693597</ixx>
          <ixy>-1.11445e-12</ixy>
          <ixz>1.46338e-26</ixz>
          <iyy>0.0672265</iyy>
          <iyz>8.14352e-18</iyz>
          <izz>0.0027375</izz>
        </inertia>
      </inertial>
      <collision name='wrist_3_link_collision'>
        <pose frame=''>0 0 0 0 -0 0</pose>
        <geometry>
          <mesh>
            <scale>1 1 1</scale>
            <uri>model://ur_description/meshes/ur10/collision/wrist3.stl</uri>
          </mesh>
        </geometry>
        <surface>
          <contact>
            <ode>
              <kp>7000</kp>
              <kd>1</kd>
            </ode>
          </contact>
          <friction>
            <ode>
              <mu>0.5</mu>
              <mu2>0.5</mu2>
            </ode>
          </friction>
        </surface>
      </collision>
      <collision name='wrist_3_link_fixed_joint_lump__ee_link_collision_1'>
        <pose frame=''>-0 0.0822 0 0 -0 1.5708</pose>
        <geometry>
          <box>
            <size>0.01 0.01 0.01</size>
          </box>
        </geometry>
        <surface>
          <contact>
            <ode>
              <kp>7000</kp>
              <kd>1</kd>
            </ode>
          </contact>
          <friction>
            <ode>
              <mu>0.5</mu>
              <mu2>0.5</mu2>
            </ode>
          </friction>
        </surface>
      </collision>
      <collision name='wrist_3_link_fixed_joint_lump__forcesensor_link_collision_2'>
        <pose frame=''>0 0.1097 0 3.14159 1.57079 -1.57079</pose>
        <geometry>
          <cylinder>
            <length>0.07</length>
            <radius>0.0175</radius>
          </cylinder>
        </geometry>
        <surface>
          <contact>
            <ode>
              <kp>7000</kp>
              <kd>1</kd>
            </ode>
          </contact>
          <friction>
            <ode>
              <mu>0.5</mu>
              <mu2>0.5</mu2>
            </ode>
          </friction>
        </surface>
      </collision>
      <collision name='wrist_3_link_fixed_joint_lump__bolt_link_collision_3'>
        <pose frame=''>0 0.1347 0 3.14159 0 -1.5708</pose>
        <geometry>
          <cylinder>
            <length>2</length>
            <radius>0.0075</radius>
          </cylinder>
        </geometry>
        <surface>
          <contact>
            <ode>
              <kp>7000</kp>
              <kd>1</kd>
            </ode>
          </contact>
          <friction>
            <ode>
              <mu>0.5</mu>
              <mu2>0.5</mu2>
            </ode>
          </friction>
        </surface>
      </collision>
      <visual name='wrist_3_link_visual'>
        <pose frame=''>0 0 0 0 -0 0</pose>
        <geometry>
          <mesh>
            <scale>1 1 1</scale>
            <uri>model://ur_description/meshes/ur10/visual/wrist3.dae</uri>
          </mesh>
        </geometry>
        <material>
          <script>
            <uri>__default__</uri>
            <name>__default__</name>
          </script>
        </material>
      </visual>
      <visual name='wrist_3_link_fixed_joint_lump__forcesensor_link_visual_1'>
        <pose frame=''>0 0.1097 0 3.14159 1.57079 -1.57079</pose>
        <geometry>
          <cylinder>
            <length>0.035</length>
            <radius>0.035</radius>
          </cylinder>
        </geometry>
        <material>
          <script>
            <uri>__default__</uri>
            <name>__default__</name>
          </script>
        </material>
      </visual>
      <visual name='wrist_3_link_fixed_joint_lump__bolt_link_visual_2'>
        <pose frame=''>0 0.1347 0 3.14159 0 -1.5708</pose>
        <geometry>
          <cylinder>
            <length>2</length>
            <radius>0.0075</radius>
          </cylinder>
        </geometry>
        <material>
          <script>
            <uri>__default__</uri>
            <name>__default__</name>
          </script>
        </material>
      </visual>
      <velocity_decay/>
      <velocity_decay/>
      <velocity_decay/>
      <sensor name='forcesensor_link_contact_sensor' type='contact'>
        <always_on>1</always_on>
        <update_rate>1000</update_rate>
        <contact>
          <topic>/contact_forces</topic>
          <collision>ee_link_collision_forcesensor_link</collision>
        </contact>
        <plugin name='forcesensor_link_bumper' filename='libreload_contact_sensor_plugin.so'>
          <robotNamespace>/</robotNamespace>
          <bumperTopicName>/impedance_controller/contact_forces</bumperTopicName>
          <frameName>forcesensor_link</frameName>
        </plugin>
        <pose frame=''>0 0.1097 0 3.14159 1.57079 -1.57079</pose>
      </sensor>
      <gravity>1</gravity>
      <velocity_decay/>
      <self_collide>1</self_collide>
    </link>
    <joint name='wrist_3_joint' type='revolute'>
      <child>wrist_3_link</child>
      <parent>wrist_2_link</parent>
      <axis>
        <xyz>0 1 0</xyz>
        <limit>
          <lower>-6.28319</lower>
          <upper>6.28319</upper>
          <effort>54</effort>
          <velocity>3.2</velocity>
        </limit>
        <dynamics>
          <damping>0</damping>
          <friction>0</friction>
          <spring_reference>0</spring_reference>
          <spring_stiffness>0</spring_stiffness>
        </dynamics>
        <use_parent_model_frame>1</use_parent_model_frame>
      </axis>
    </joint>
    <static>0</static>
    <plugin name='ros_control' filename='libgazebo_ros_control.so'/>
  </model>
</sdf>
